<?xml version='1.0'?>

<robot name="myrobot" xmlns:xacro="http://www.ros.org/wiki/xacro">

  <xacro:include filename="$(find robot_one_description)/urdf/robot_one.gazebo" />
  <xacro:include filename="$(find robot_one_description)/urdf/materials.xacro" />
 

  <xacro:property name="D_ROBO" value="0.5" />
  <xacro:property name="EIXO_ROBO" value="0.00635" />
  <xacro:property name="PI" value="3.1415926535897931" />


  <!-- Base Robotic -->
  <link name="base_link">
    <inertial>
      <mass value="2" />
      <origin xyz="0 0 0.0" />
      <inertia ixx="0.01" ixy="0.0" ixz="0.0"
        iyy="0.01" iyz="0.0" izz="0.5" />
    </inertial>

      <visual>
        <origin xyz="0 0 0" rpy="0 0 0" />
        <geometry>
          <cylinder length="0.0095" radius="${D_ROBO/2}"/>
        </geometry>
        <material name ="White" />
      </visual>

      <collision>
        <origin xyz="0 0 0" rpy="0 0 0" />
        <geometry>
          <cylinder length="0.0095" radius="${D_ROBO/2}"/>
        </geometry>
      </collision>
  </link>


  <!-- Caster Whells -->
  <link name="front_caster">
    <inertial>
      <mass value="0.001" />
      <origin xyz="0 0 0" />
      <inertia ixx="0.0001" ixy="0.0" ixz="0.0"
          iyy="0.0001" iyz="0.0"
          izz="0.0001" />
    </inertial>

      <visual>
        <origin xyz="0 0 0" rpy="-1.5707 0 1.5707" />
        <geometry>
          <mesh filename="package://robot_one_description/meshes/castor.dae"/>
        </geometry>
        <material name ="light_grey">
          <color rgba="0.6 0.6 0.6 1"/>
        </material>
      </visual>

      <collision>
        <origin xyz="0 0 0" rpy="-1.5707 0 1.5707" />
        <geometry>
          <mesh filename="package://robot_one_description/meshes/castor.dae"/>
        </geometry>
      </collision>
  </link>

  <joint name="front_caster_joint" type="fixed">
    <origin xyz="0.18745 0 -0.00475" rpy="0 0 0" />
    <parent link="base_link" />
    <child link="front_caster" />
  </joint>  



  <link name="rear_caster">
    <inertial>
      <mass value="0.001" />
      <origin xyz="0 0 0" />
      <inertia ixx="0.0001" ixy="0.0" ixz="0.0"
        iyy="0.0001" iyz="0.0"
        izz="0.0001" />
      </inertial>

      <visual>
        <origin xyz="0 0 0" rpy="-1.5707 0 1.5707" />
        <geometry>
          <mesh filename="package://robot_one_description/meshes/castor.dae"/>
        </geometry>
        <material name ="light_grey">
          <color rgba="0.6 0.6 0.6 1"/>
        </material>
      </visual>

      <collision>
        <origin xyz="0 0 0" rpy="-1.5707 0 1.5707" />
        <geometry>
      <mesh filename="package://robot_one_description/meshes/castor.dae"/>
        </geometry>
      </collision>
  </link>

  <joint name="rear_caster_joint" type="fixed">
    <origin xyz="-0.18745 0 -0.00475" rpy="0 0 0" />
    <parent link="base_link" />
    <child link="rear_caster" />
  </joint>






  <!-- Axles -->
  <link name="left_axle_link">
    <inertial>
      <origin xyz="0 0 0"/>
      <mass value="0.01" />
      <inertia ixx="0.001" ixy="0.0" ixz="0.0"
        iyy="0.001" iyz="0.0" izz="0.001" />
      </inertial>

      <visual>
        <origin xyz="0 0 0" rpy="0 ${PI/2} ${PI/2}" />
        <geometry>
          <cylinder radius="${EIXO_ROBO}" length = "${EIXO_ROBO}"/>
        </geometry>
        <material name ="light_grey" />
      </visual>

      <collision>
        <origin xyz="0 0 0" rpy="0 ${PI/2} ${PI/2}" />
        <geometry>
          <cylinder radius="${EIXO_ROBO}" length = "${EIXO_ROBO}"/>
        </geometry>
      </collision>
  </link>

  <joint name="left_axle_joint" type="fixed">
    <origin xyz="0 ${D_ROBO/2 + EIXO_ROBO} 0" rpy="0 0 0"/>
    <parent link="base_link"/>
    <child link="left_axle_link"/>
    <axis xyz="0 1 0"/>
  </joint>


  <link name="right_axle_link">
    <inertial>
      <origin xyz="0 0 0"/>
      <mass value="0.01" />
      <inertia ixx="0.001" ixy="0.0" ixz="0.0"
        iyy="0.001" iyz="0.0" izz="0.001" />
      </inertial>

      <visual>
        <origin xyz="0 0 0" rpy="0 ${PI/2} ${PI/2}" />
        <geometry>
          <cylinder radius="${EIXO_ROBO}" length = "${EIXO_ROBO}"/>
        </geometry>
        <material name ="light_grey" />
      </visual>

      <collision>
        <origin xyz="0 0 0" rpy="0 ${PI/2} ${PI/2}" />
        <geometry>
          <cylinder radius="${EIXO_ROBO}" length = "${EIXO_ROBO}"/>
        </geometry>
      </collision>
  </link>

  <joint name="right_axle_joint" type="fixed">
    <origin xyz="0 -${D_ROBO/2 + EIXO_ROBO} 0" rpy="0 0 0"/>
    <parent link="base_link"/>
    <child link="right_axle_link"/>
    <axis xyz="0 1 0"/>
  </joint>



  <!-- Wheels -->
  
  <link name="left_wheel_link">
    <inertial>
      <origin xyz="0 0 0"/>
      <mass value="0.01" />
      <inertia ixx="0.001" ixy="0.0" ixz="0.0"
        iyy="0.001" iyz="0.0" izz="0.001" />
      </inertial>

      <visual>
        <origin xyz="0 0 0" rpy="0 1.5707 1.5707" />
        <geometry>
          <cylinder radius="0.0762" length = "0.03175"/>
        </geometry>
        <material name ="black" />
      </visual>

      <collision>
        <origin xyz="0 0 0" rpy="0 1.5707 1.5707" />
        <geometry>
          <cylinder radius="0.076" length = "0.03175"/>
        </geometry>
      </collision>
  </link>

  <joint name="left_wheel_joint" type="continuous">
    <origin xyz="0 0.01905 0" rpy="0 0 0"/>
    <parent link="left_axle_link"/>
    <child link="left_wheel_link"/>
    <axis xyz="0 1 0"/>
  </joint>



  <link name="right_wheel_link">
    <inertial>
      <origin xyz="0 0 0"/>
      <mass value="0.01" />
      <inertia ixx="0.001" ixy="0.0" ixz="0.0"
        iyy="0.001" iyz="0.0" izz="0.001" />
      </inertial>

      <visual>
        <origin xyz="0 0 0" rpy="0 1.5707 1.5707" />
        <geometry>
          <cylinder radius="0.0762" length = "0.03175"/>
        </geometry>
        <material name ="black" />
      </visual>

      <collision>
        <origin xyz="0 0 0" rpy="0 1.5707 1.5707" />
        <geometry>
          <cylinder radius="0.076" length = "0.03175"/>
        </geometry>
      </collision>
  </link>

  <joint name="right_wheel_joint" type="continuous">
    <origin xyz="0 -0.01905 0" rpy="0 0 0"/>
    <parent link="right_axle_link"/>
    <child link="right_wheel_link"/>
    <axis xyz="0 1 0"/>
  </joint>


</robot>